Workbook

Sheet Leeme
A1: Tablero de validación: IPS Salud y Vida
A3: Para qué es | B3: Validar, entre los cuatro y en línea, el anexo técnico de la Resolución 866 de 2021 contra las 33 historias entregadas, antes de mover cambios a Trello. Trello sigue siendo el backlog que evalúa el docente; este archivo es el lugar de trabajo.
A4: Un solo archivo | B4: Se trabaja solo en línea, en este enlace. Nadie descarga, edita en su equipo y vuelve a subir: eso pisa el trabajo de los demás.
A5: Colores de columna | B5: Encabezado gris oscuro y celdas grises: referencia, no se edita. Encabezado azul y celdas amarillas: se llenan. Encabezado gris medio: fórmulas, no se tocan.
A6: Fuente que manda | B6: El PDF del anexo, hojas 13 a 25. Las columnas "referencia" de la hoja Validación son una transcripción hecha con IA: sirven para guiarse, y si no coinciden con la hoja del PDF, manda la hoja.
A7: Ajustes al prompt | B7: Antes de analizar cualquier fila, leer la hoja Ajustes al prompt, que es el mismo texto del archivo ajustes-prompt-v2.1.md. Aplican a todos los bloques desde el 2026-10-18 y mandan sobre el prompt v2.1 donde choquen.
A8: Protocolo | B8: 1. Para tomar una fila: primero tu nombre en Responsable, después Estado en "En análisis". La columna "¿Se puede tomar?" cambia sola.
B9: 2. Al terminar: Estado en "Analizado", con Fuente del análisis y Detalle de la fuente llenos. La fila queda como "Lista para revisar".
B10: 3. Otra persona revisa contra el PDF, se pone como Revisor y cambia el Estado a "Aprobado". Nadie aprueba lo suyo: la columna Alerta lo marca.
B11: 4. Solo lo aprobado pasa a Trello. El comentario de la tarjeta copia la fuente y la fecha de la fila, y aquí se anota el ID en Trello con Estado "En Trello".
B12: Si falta una decisión del equipo para seguir: Estado "Bloqueado" y en "Bloqueada por" el número de la hoja Decisiones, por ejemplo D-02.
A14: Ejemplo de fila tomada | B14: Responsable: Juliana · Estado: En análisis · Fuente del análisis: Hoja del PDF del anexo · Detalle de la fuente: hoja 15, fila del elemento 12 · Fecha de inicio: 2026-10-18
A15: Estado al 2026-10-20 | B15: Al 2026-10-20 las 28 filas de Validación y las 33 historias están analizadas por Juan Fernando con apoyo de un modelo. V-18 queda bloqueada por D-05. La revisión la hace otra persona: Revisor distinto de Responsable. Criterio de la columna L: “Sí” solo si las columnas F a K coinciden con la hoja letra por letra, salvo separadores; una paráfrasis o una tilde distinta cuenta como diferencia. Una revisión independiente cotejó las 28 filas contra las hojas 13 a 18. Resumen de entidades y conteo de historias en la hoja Entidades. Los elementos 24 a 49 no están en el tablero: dependen de D-16. Las celdas L2:L22 se habían llenado por arrastre y se rehicieron contra las hojas del PDF. Retroalimentación: los 63 comentarios del docente de HU-001 a HU-030, de la exportación de Trello del 19 oct 2026; HU-031 a HU-033 no están en esa exportación. Ajustes por historia en lenguaje simple: cada historia remite al numeral del anexo en vez de copiar formatos.
A16: Reparto sugerido | B16: Todas las filas están analizadas por Juan Fernando. Cada integrante toma un bloque como Revisor (columna Z), contra el PDF, y cambia el Estado a Aprobado o lo devuelve. Bloque A, elementos 1 a 6 · Bloque B, 7 a 12 · Bloque C, 13 a 18 · Bloque D, 19 a 23. Las historias se revisan con la hoja Ajustes por historia.
A17: El mapa | B17: mapa-anexo-vs-backlog.md se abre cuando cada uno termine su bloque, para comparar. Antes de eso condiciona la validación.
A19: Hojas | B19: Validación: una fila por componente del anexo. Historias: las 33 entregadas, texto sin cambios. Por redactar: IDs reservados para las historias que falten. Decisiones: lo que el equipo debe acordar. Retroalimentación: los textos del docente tal como llegaron. Escenarios: los criterios BDD de las 33. Reglas comunes: RC-1 a RC-11 (RC-6 a RC-11 son del backlog v3). Ajustes por historia: una fila por historia y fila de validación; los ajustes van ahí y no en la hoja Historias, para que dos bloques no escriban en la misma celda. Ajustes al prompt: correcciones al prompt v2.1. Entidades: cada entidad con su regla, sus historias existentes y nuevas, y el total del backlog según D-17. Historias, columnas R a T: resultado y resumen por historia; el detalle por escenario sigue en Ajustes por historia. Anexo 1 a 49: una fila por componente de los 49 elementos, con lo que cubre este backlog, lo que cubren los compañeros y lo que falta; del 24 al 49 la clasificación es preliminar (D-16). Backlog v3: las 30 historias del plan de reescritura, con su origen, su tanda, su estado y el archivo de su borrador (carpeta backlog-v3); las hojas Ajustes por historia y Retroalimentación dicen a qué historia del v3 va cada fila.
A21: Avance | B21: Cantidad
A22: Validación: libres | B22: =COUNTIF(Validación!T:T,"Libre") -> 0
A23: Validación: en análisis | B23: =COUNTIF(Validación!T:T,"En análisis") -> 0
A24: Validación: analizadas | B24: =COUNTIF(Validación!T:T,"Analizado") -> 27
A25: Validación: en revisión | B25: =COUNTIF(Validación!T:T,"En revisión") -> 0
A26: Validación: aprobadas | B26: =COUNTIF(Validación!T:T,"Aprobado") -> 0
A27: Validación: bloqueadas | B27: =COUNTIF(Validación!T:T,"Bloqueado") -> 1
A28: Validación: filas con alerta | B28: =COUNTIF(Validación!V2:V200,"?*") -> 0
A29: Historias: filas con alerta | B29: =COUNTIF(Historias!X2:X200,"?*") -> 0
A30: Historias: resultado Cumple | B30: =COUNTIF(Historias!R:R,"Cumple") -> 0
A31: Historias: resultado Ajustar | B31: =COUNTIF(Historias!R:R,"Ajustar") -> 33
A32: Historias: resultado Sobra | B32: =COUNTIF(Historias!R:R,"Sobra") -> 0
A33: Historias: libres | B33: =COUNTIF(Historias!V:V,"Libre") -> 0
A34: Historias: aprobadas o en Trello | B34: =COUNTIF(Historias!V:V,"Aprobado")+COUNTIF(Historias!V:V,"En Trello") -> 0
A35: Historias por redactar en uso | B35: =COUNTA('Por redactar'!C:C)-1 -> 0
A36: Decisiones pendientes | B36: =COUNTIF(Decisiones!E:E,"Pendiente") -> 27
A37: Ajustes por historia: filas | B37: =COUNTA('Ajustes por historia'!A:A)-1 -> 104
A38: Total de historias si D-17 = una por operación | B38: =Entidades!H23 -> 69
A39: Total de historias si D-17 = una por entidad | B39: =Entidades!I23 -> 24

Sheet Ajustes al prompt
A1: N.º | B1: Ajuste al prompt v2.1 (2026-10-18). Mismo texto que ajustes-prompt-v2.1.md
A2: 1 | B2: Umbral. El numeral 2.3 dice "más de 5 opciones seleccionables" y la revisión General del docente lo repite ("campos con más de cinco opciones"). Usa más de 5. Una lista de exactamente 5 valores es campo, y en Observaciones escribe "Depende de D-01".
A3: 2 | B3: Reutilizar va antes de las preguntas 2 y 3. Si otro componente usa el mismo catálogo, la entidad es de la fila con el número V más bajo; las demás filas se clasifican "Reutiliza otra entidad" y no proponen historias. Ejemplo: V-01 crea Países y V-12 la reutiliza.
A4: 3 | B4: El numeral 2.1 de la guía tiene 7 filas, no 2. Además de las dos estructuras separadas: un paciente puede tener más de un país de nacionalidad; la fecha de nacimiento se separa de la hora; la ocupación solo admite las ocupaciones hijas del CIUO-88 AC; un paciente puede registrar más de una discapacidad; la ciudad de residencia se registra con su código DANE. Cada una da al menos un escenario en las historias del paciente; HU-004 a HU-006 ya las tienen.
A5: 4 | B5: Escenarios que le faltan a la tabla del prompt: dato con varios valores (se aceptan dos o más); catálogo donde solo se eligen hijas (una categoría padre se rechaza); fecha con longitud mínima 10 y máxima 16 (la hora puede faltar); código con cero inicial ("1" en vez de "01" se rechaza por la longitud mínima).
A6: 5 | B6: Tipos (propuesta D-18). Cada componente se guarda con el tipo de la columna Tipo de la hoja: Alfanumérico es texto de la longitud indicada, aunque sus valores se vean como cifras; Numérico es entero; Fecha es fecha y hora. En los elementos 1 a 23 todos los códigos son Alfanumérico.
A7: 6 | B7: Los datos de los elementos 16 a 23 son de la atención (el contacto con el servicio de salud), no de la historia clínica. Si el componente es campo, en Entidad escribe "Atención". Si es catálogo, la atención guarda el código que apunta a él.
A8: 7 | B8: Catálogos y artículo 7 de la Resolución 866: los catálogos "no podrán ser modificados, reducidos o adicionados". El CRUD que pide el numeral 2.3 crea y actualiza solo para reflejar el catálogo oficial, con su fuente y versión. El llenado inicial de catálogos grandes (CIE-10, DIVIPOLA, CIUO-88, ISO 3166-1) es tarea técnica del equipo, no historia de usuario. No uses "cargar" en una historia.
A9: 8 | B9: El nombre que corresponde a un código va en la misma entidad que el código y no es texto libre. Solo los elementos 1, 7, 11, 12, 15 y 23 traen el nombre como componente propio (Alfanumérico, máximo 200, mínimo 3); en los demás, los nombres están solo dentro de los valores permitidos.
A10: 9 | B10: RC-3 dice "sincronizada". No copies esa palabra en una historia; escribe "PENDIENTE reescribir RC-3".
A11: 10 | B11: Historias nuevas: en la columna "Historias nuevas propuestas" escribe "4 historias; IDs en espera de D-17". No reserves IDs en Por redactar hasta que se decida D-17 (una historia por operación del CRUD o una por entidad).
A12: 11 | B12: Los ajustes a historias existentes van a la hoja "Ajustes por historia", una fila por historia y fila de validación. No escribas en la columna Resultado de la hoja Historias: se consolida al final.
A13: 12 | B13: El prestador (elementos 9 y 16) depende de D-05. Mientras esté Pendiente, clasifícalo "Pendiente de decisión".
... A16: 15 | B16: Las filas V-22 a V-26 (bloque D) ya están analizadas. Sirven de ejemplo del formato de las columnas, no de la clasificación de otros bloques.

Sheet Validación
A1: Fila | B1: Bloque | C1: Elemento | D1: Componente | E1: Hoja del PDF | F1: Valores (referencia) | G1: N.º de valores (referencia) | H1: Tipo (referencia) | I1: Formato (referencia) | J1: Long. máx. (referencia) | K1: Long. mín. (referencia) | L1: ¿Transcripción confirmada contra el PDF? | M1: N.º de valores contado en el PDF | N1: Clasificación | O1: Entidad | P1: Pregunta del prompt que decidió (1 a 5) | Q1: Historias existentes que lo cubren | R1: Historias nuevas propuestas | S1: Responsable | T1: Estado | U1: ¿Se puede tomar? | V1: Alerta | W1: Fuente del análisis | X1: Detalle de la fuente | Y1: Bloqueada por | Z1: Revisor | AA1: Fecha de inicio | AB1: Fecha de cierre | AC1: Observaciones y diferencias
A2: V-01 | B2: A | C2: 1 | D2: Código y nombre del país de nacionalidad | E2: 13 | F2: Código a tres caracteres según estándar ISO 3166-1. Nombre correspondiente al código | G2: El anexo no los enumera | H2: Alfanumérico | I2: 999 / sin formato | J2: 3 / 200 | K2: 3 / 3 | L2: No: hay diferencias | M2: No los enumera | N2: Entidad por 2.3 | O2: Países | P2: 2 | Q2: HU-018 a HU-021 cubren el CRUD (Ajustar). HU-004 a HU-006 usan el dato; los escenarios de varias nacionalidades cumplen. | R2: ninguna | S2: Juan Fernando | T2: Analizado | U2: =IF(OR(T2="",T2="Libre"),"Disponible",IF(T2="Bloqueado","Bloqueada: "&IF(Y2="","falta motivo",Y2),IF(OR(T2="Aprobado",T2="En Trello"),"Cerrada",IF(T2="En revisión","En revisión: "&IF(Z2="","falta revisor",Z2),IF(T2="Analizado","Lista para revisar: analizó "&IF(S2="","falta responsable",S2),IF(S2="","Falta responsable","Ocupada por "&S2)))))) -> Lista para revisar: analizó Juan Fernando | V2: =IF(AND(Z2<>"",Z2=S2),"El revisor no puede ser el responsable",IF(AND(OR(T2="Analizado",T2="En revisión",T2="Aprobado"),W2=""),"Falta la fuente del análisis",IF(AND(OR(T2="Aprobado",T2="En Trello"),Z2=""),"Aprobado sin revisor",""))) | W2: Prompt con IA | X2: Hoja 13, elemento 1: código ISO 3166-1 (alfanumérico, 999, 3 y 3) y nombre (alfanumérico, 200 y 3). Numeral 2.1: más de un país de nacionalidad. Numeral 2.3: catálogo externo. | AA2: 46315 | AC2: La hoja 13 deja vacíos los valores permitidos del nombre del país; la referencia escribe “Nombre correspondiente al código”. Coinciden tipos, formatos y longitudes. Código ISO 3166-1 de 3 caracteres, alfabético o numérico: PENDIENTE D-03. Varias nacionalidades por paciente (2.1): relación de muchos a muchos entre paciente y país. Fuente y versión del catálogo: PENDIENTE D-21. Carga desde el archivo oficial: funcionalidad de la historia del catálogo (el docente la da por funcional).
A3: V-02 | B3: A | C3: 2 | D3: Tipo de documento de identificación | E3: 13 | F3: CC Cédula ciudadanía · CE Cédula de extranjería · CD Carné diplomático · PA Pasaporte · SC Salvoconducto de permanencia · PT Permiso Temporal de Permanencia · PE Permiso Especial de Permanencia · RC Registro civil · TI Tarjeta de identidad · CN Certificado de nacido vivo · AS Adulto sin identificar · MS Menor sin identificar · DE Documento extranjero · SI Sin identificación | G3: 14 | H3: Alfanumérico | I3: 99 | J3: 2 | K3: 2 | L3: Sí | M3: 14 | N3: Entidad por 2.3 | O3: Tipos de documento de identificación | P3: 3 | Q3: Ninguna cubre el CRUD. HU-004 a HU-006 usan el dato (Ajustar). | R3: 4 historias; IDs en espera de D-17 | S3: Juan Fernando | T3: Analizado | U3: =IF(OR(T3="",T3="Libre"),"Disponible",IF(T3="Bloqueado","Bloqueada: "&IF(Y3="","falta motivo",Y3),IF(OR(T3="Aprobado",T3="En Trello"),"Cerrada",IF(T3="En revisión","En revisión: "&IF(Z3="","falta revisor",Z3),IF(T3="Analizado","Lista para revisar: analizó "&IF(S3="","falta responsable",S3),IF(S3="","Falta responsable","Ocupada por "&S3)))))) -> Lista para revisar: analizó Juan Fernando | V3: =IF(AND(Z3<>"",Z3=S3),"El revisor no puede ser el responsable",IF(AND(OR(T3="Analizado",T3="En revisión",T3="Aprobado"),W3=""),"Falta la fuente del análisis",IF(AND(OR(T3="Aprobado",T3="En Trello"),Z3=""),"Aprobado sin revisor",""))) | W3: Prompt con IA | X3: Hoja 13, elemento 2: 14 valores, alfanumérico, formato 99, longitud 2 y 2. Numeral 2.3: más de 5 opciones. Retroalimentación HU-004: clave del duplicado por tipo y número. | AA3: 46315 | AC3: Coinciden los 14 valores, tipo, formato y longitudes. Clave de paciente duplicado: tipo y número de documento, PENDIENTE D-07. Cargo que mantiene el catálogo: PENDIENTE D-02. Representación del código: PENDIENTE D-18.
A4: V-03 | B4: A | C4: 2 | D4: Número de documento de identificación | E4: 13 | F4: Conjunto de caracteres asignados a una persona de acuerdo con el tipo de documento | G4: No aplica: dato abierto | H4: Alfanumérico | I4: sin formato | J4: 20 | K4: 3 | L4: No: hay diferencias | M4: No aplica | N4: Campo del paciente | O4: Paciente | P4: 5 | Q4: HU-004, HU-005, HU-006 (Ajustar). | R4: ninguna | S4: Juan Fernando | T4: Analizado | U4: =IF(OR(T4="",T4="Libre"),"Disponible",IF(T4="Bloqueado","Bloqueada: "&IF(Y4="","falta motivo",Y4),IF(OR(T4="Aprobado",T4="En Trello"),"Cerrada",IF(T4="En revisión","En revisión: "&IF(Z4="","falta revisor",Z4),IF(T4="Analizado","Lista para revisar: analizó "&IF(S4="","falta responsable",S4),IF(S4="","Falta responsable","Ocupada por "&S4)))))) -> Lista para revisar: analizó Juan Fernando | V4: =IF(AND(Z4<>"",Z4=S4),"El revisor no puede ser el responsable",IF(AND(OR(T4="Analizado",T4="En revisión",T4="Aprobado"),W4=""),"Falta la fuente del análisis",IF(AND(OR(T4="Aprobado",T4="En Trello"),Z4=""),"Aprobado sin revisor",""))) | W4: Prompt con IA | X4: Hoja 13, elemento 2: número de documento, alfanumérico, longitud 20 y 3, dato abierto. | AA4: 46315 | AC4: La referencia abrevia el texto de la hoja (“…para efectos de identidad e individualización dentro del territorio nacional”). Dato abierto de 3 a 20 caracteres alfanuméricos. Con el tipo forma la clave del duplicado (D-07).
A5: V-04 | B5: A | C5: 3 | D5: Primer apellido, segundo apellido, primer nombre, segundo nombre | E5: 13 | F5: Según el documento de identificación | G5: No aplica: dato abierto | H5: Alfanumérico | I5: sin formato | J5: 60 cada uno | K5: 2 cada uno | L5: No: hay diferencias | M5: No aplica | N5: Campo del paciente | O5: Paciente | P5: 5 | Q5: HU-004, HU-005, HU-006 (Ajustar). | R5: ninguna | S5: Juan Fernando | T5: Analizado | U5: =IF(OR(T5="",T5="Libre"),"Disponible",IF(T5="Bloqueado","Bloqueada: "&IF(Y5="","falta motivo",Y5),IF(OR(T5="Aprobado",T5="En Trello"),"Cerrada",IF(T5="En revisión","En revisión: "&IF(Z5="","falta revisor",Z5),IF(T5="Analizado","Lista para revisar: analizó "&IF(S5="","falta responsable",S5),IF(S5="","Falta responsable","Ocupada por "&S5)))))) -> Lista para revisar: analizó Juan Fernando | V5: =IF(AND(Z5<>"",Z5=S5),"El revisor no puede ser el responsable",IF(AND(OR(T5="Analizado",T5="En revisión",T5="Aprobado"),W5=""),"Falta la fuente del análisis",IF(AND(OR(T5="Aprobado",T5="En Trello"),Z5=""),"Aprobado sin revisor",""))) | W5: Prompt con IA | X5: Hoja 13, elemento 3: primer y segundo apellido, primer y segundo nombre, alfanumérico, longitud 60 y 2 cada uno. | AA5: 46315 | AC5: Cuatro componentes con los mismos límites: 2 a 60 caracteres. Que se acepten tildes, ñ y espacios es un supuesto a confirmar con el equipo. Cuáles son obligatorios (el segundo nombre y el segundo apellido pueden no existir): PENDIENTE D-19. La hoja escribe “De acuerdo como se especifica en el documento de identificación”; la referencia, “Según el documento de identificación”.
A6: V-05 | B6: A | C6: 4 | D6: Fecha y hora de nacimiento | E6: 13 | F6: Según el documento de identificación o como la declare el individuo | G6: No aplica: dato abierto | H6: Fecha | I6: AAAA-MM-DD HH:MM | J6: 16 | K6: 10 | L6: No: hay diferencias | M6: No aplica | N6: Campo del paciente | O6: Paciente | P6: 5 | Q6: HU-004, HU-005, HU-006. Los escenarios de fecha separada de la hora y de hora faltante cumplen; faltan los de formato (Ajustar). | R6: ninguna | S6: Juan Fernando | T6: Analizado | U6: =IF(OR(T6="",T6="Libre"),"Disponible",IF(T6="Bloqueado","Bloqueada: "&IF(Y6="","falta motivo",Y6),IF(OR(T6="Aprobado",T6="En Trello"),"Cerrada",IF(T6="En revisión","En revisión: "&IF(Z6="","falta revisor",Z6),IF(T6="Analizado","Lista para revisar: analizó "&IF(S6="","falta responsable",S6),IF(S6="","Falta responsable","Ocupada por "&S6)))))) -> Lista para revisar: analizó Juan Fernando | V6: =IF(AND(Z6<>"",Z6=S6),"El revisor no puede ser el responsable",IF(AND(OR(T6="Analizado",T6="En revisión",T6="Aprobado"),W6=""),"Falta la fuente del análisis",IF(AND(OR(T6="Aprobado",T6="En Trello"),Z6=""),"Aprobado sin revisor",""))) | W6: Prompt con IA | X6: Hoja 13, elemento 4: Fecha, AAAA-MM-DD HH:MM, longitud 16 y 10. Numeral 2.1: separar fecha y hora. Retroalimentación HU-004 ampliada: fecha sin hora compatible con la mínima de 10. | AA6: 46315 | AC6: La mínima de 10 permite la fecha sin hora; el numeral 2.1 pide separar fecha y hora: dos campos del paciente. Se guarda como fecha y hora: PENDIENTE D-18. La hoja escribe “De acuerdo como se especifica” donde la referencia escribe “Según”.
A7: V-06 | B7: A | C7: 5 | D7: Sexo biológico | E7: 13 | F7: 01 Hombre · 02 Mujer · 03 Indeterminado/Intersexual | G7: 3 | H7: Alfanumérico | I7: 99 | J7: 2 | K7: 2 | L7: Sí | M7: 3 | N7: Campo del paciente | O7: Paciente | P7: 5 | Q7: HU-004, HU-005, HU-006 (Ajustar). | R7: ninguna | S7: Juan Fernando | T7: Analizado | U7: =IF(OR(T7="",T7="Libre"),"Disponible",IF(T7="Bloqueado","Bloqueada: "&IF(Y7="","falta motivo",Y7),IF(OR(T7="Aprobado",T7="En Trello"),"Cerrada",IF(T7="En revisión","En revisión: "&IF(Z7="","falta revisor",Z7),IF(T7="Analizado","Lista para revisar: analizó "&IF(S7="","falta responsable",S7),IF(S7="","Falta responsable","Ocupada por "&S7)))))) -> Lista para revisar: analizó Juan Fernando | V7: =IF(AND(Z7<>"",Z7=S7),"El revisor no puede ser el responsable",IF(AND(OR(T7="Analizado",T7="En revisión",T7="Aprobado"),W7=""),"Falta la fuente del análisis",IF(AND(OR(T7="Aprobado",T7="En Trello"),Z7=""),"Aprobado sin revisor",""))) | W7: Prompt con IA | X7: Hoja 13, elemento 5: 3 valores, alfanumérico, formato 99, longitud 2 y 2. Numeral 2.3: no llega a más de 5 opciones. | AA7: 46315 | AC7: Lista de 3 valores. Campo del paciente. Se guarda como texto de 2 caracteres: PENDIENTE D-18.
A8: V-07 | B8: A | C8: 6 | D8: Identidad de género | E8: 14 | F8: 01 Masculino · 02 Femenino · 03 Transgénero · 04 Neutro · 05 No lo declara | G8: 5 | H8: Alfanumérico | I8: 99 | J8: 2 | K8: 2 | L8: Sí | M8: 5 | N8: Campo del paciente | O8: Paciente | P8: 5 | Q8: HU-004, HU-005, HU-006 (Ajustar). | R8: ninguna | S8: Juan Fernando | T8: Analizado | U8: =IF(OR(T8="",T8="Libre"),"Disponible",IF(T8="Bloqueado","Bloqueada: "&IF(Y8="","falta motivo",Y8),IF(OR(T8="Aprobado",T8="En Trello"),"Cerrada",IF(T8="En revisión","En revisión: "&IF(Z8="","falta revisor",Z8),IF(T8="Analizado","Lista para revisar: analizó "&IF(S8="","falta responsable",S8),IF(S8="","Falta responsable","Ocupada por "&S8)))))) -> Lista para revisar: analizó Juan Fernando | V8: =IF(AND(Z8<>"",Z8=S8),"El revisor no puede ser el responsable",IF(AND(OR(T8="Analizado",T8="En revisión",T8="Aprobado"),W8=""),"Falta la fuente del análisis",IF(AND(OR(T8="Aprobado",T8="En Trello"),Z8=""),"Aprobado sin revisor",""))) | W8: Prompt con IA | X8: Hoja 14, elemento 6: 5 valores, alfanumérico, formato 99, longitud 2 y 2. Numeral 2.3: no llega a más de 5 opciones. D-01. | AA8: 46315 | AC8: Lista de exactamente 5 valores. Depende de D-01: si el umbral pasa a 5 o más, cambia a Entidad por 2.3 con 4 historias nuevas.
A9: V-08 | B9: B | C9: 7 | D9: Código y nombre de la ocupación | E9: 14 | F9: Catálogo CIUO-88 A.C., Clasificación Internacional Uniforme de Ocupaciones Adaptada para Colombia por el DANE. Nombre correspondiente al código | G9: El anexo no los enumera | H9: Alfanumérico | I9: 9999 / sin formato | J9: 4 / 200 | K9: 4 / 3 | L9: Sí | M9: No los enumera | N9: Entidad por 2.3 | O9: Ocupaciones | P9: 2 | Q9: HU-022 a HU-025 cubren el CRUD (Ajustar). HU-004 a HU-006 usan el dato; los escenarios de solo ocupaciones hijas cumplen. | R9: ninguna | S9: Juan Fernando | T9: Analizado | U9: =IF(OR(T9="",T9="Libre"),"Disponible",IF(T9="Bloqueado","Bloqueada: "&IF(Y9="","falta motivo",Y9),IF(OR(T9="Aprobado",T9="En Trello"),"Cerrada",IF(T9="En revisión","En revisión: "&IF(Z9="","falta revisor",Z9),IF(T9="Analizado","Lista para revisar: analizó "&IF(S9="","falta responsable",S9),IF(S9="","Falta responsable","Ocupada por "&S9)))))) -> Lista para revisar: analizó Juan Fernando | V9: =IF(AND(Z9<>"",Z9=S9),"El revisor no puede ser el responsable",IF(AND(OR(T9="Analizado",T9="En revisión",T9="Aprobado"),W9=""),"Falta la fuente del análisis",IF(AND(OR(T9="Aprobado",T9="En Trello"),Z9=""),"Aprobado sin revisor",""))) | W9: Prompt con IA | X9: Hoja 14, elemento 7: código CIUO-88 A.C. (alfanumérico, 9999, 4 y 4) y nombre (200 y 3). Numeral 2.1: solo ocupaciones hijas. Numeral 2.3: catálogo externo. | AA9: 46315 | AC9: Código de exactamente 4 caracteres: solo se asocian ocupaciones de ese nivel, coherente con “solo las ocupaciones hijas” del 2.1. Que la CIUO-88 A.C. tenga niveles de 1 a 3 caracteres por encima es inferencia del modelo, no está en la hoja. Fuente y versión del catálogo: PENDIENTE D-21. Carga desde el archivo oficial: funcionalidad de la historia del catálogo (el docente la da por funcional).
A10: V-09 | B10: B | C10: 8 | D10: Manifestación de oposición a la presunción legal de donación, y fecha del documento | E10: 14 | F10: 01 Sí · 02 No. Fecha en que se suscribe el documento válido ante el INS o la entidad administradora del plan de beneficios | G10: 2 | H10: Alfanumérico / Fecha | I10: 99 / AAAA-MM-DD | J10: 2 / 10 | K10: 2 / 10 | L10: No: hay diferencias | M10: 2 | N10: Entidad por 2.1 | O10: Oposición a la presunción legal de donación | P10: 1 | Q10: HU-010 a HU-013 (Ajustar). | R10: ninguna | S10: Juan Fernando | T10: Analizado | U10: =IF(OR(T10="",T10="Libre"),"Disponible",IF(T10="Bloqueado","Bloqueada: "&IF(Y10="","falta motivo",Y10),IF(OR(T10="Aprobado",T10="En Trello"),"Cerrada",IF(T10="En revisión","En revisión: "&IF(Z10="","falta revisor",Z10),IF(T10="Analizado","Lista para revisar: analizó "&IF(S10="","falta responsable",S10),IF(S10="","Falta responsable","Ocupada por "&S10)))))) -> Lista para revisar: analizó Juan Fernando | V10: =IF(AND(Z10<>"",Z10=S10),"El revisor no puede ser el responsable",IF(AND(OR(T10="Analizado",T10="En revisión",T10="Aprobado"),W10=""),"Falta la fuente del análisis",IF(AND(OR(T10="Aprobado",T10="En Trello"),Z10=""),"Aprobado sin revisor",""))) | W10: Prompt con IA | X10: Hoja 14, elemento 8: manifestación (01 Sí, 02 No; alfanumérico, 99, 2 y 2) y fecha de suscripción del documento (Fecha, AAAA-MM-DD, 10 y 10). Numeral 2.1: estructura separada (CRUD). | AA10: 46315 | AC10: Estructura separada por el 2.1. La fecha es la de suscripción del documento válido ante el Instituto Nacional de Salud o la Entidad Administradora del Plan de Beneficios; HU-010 escenario 4 usa otra fecha. Eliminar como inactivación: PENDIENTE D-20. Hoja 14: “01: Si”, sin tilde; la referencia escribe “Sí” y abrevia “Instituto Nacional de Salud” como “INS”.
A11: V-10 | B11: B | C11: 9 | D11: Documento de voluntad anticipada, fecha y código del prestador donde se encuentra | E11: 14 | F11: 01 Sí · 02 No. Fecha de suscripción, modificación, sustitución o revocación. Código del prestador donde se encuentra el documento | G11: 2 | H11: Alfanumérico / Fecha / Alfanumérico | I11: 99 / AAAA-MM-DD / 999999999999 | J11: 2 / 10 / 12 | K11: 2 / 10 / 12 | L11: No: hay diferencias | M11: 2 | N11: Entidad por 2.1 | O11: Documento de voluntad anticipada | P11: 1 | Q11: HU-014 a HU-017 (Ajustar). | R11: ninguna | S11: Juan Fernando | T11: Analizado | U11: =IF(OR(T11="",T11="Libre"),"Disponible",IF(T11="Bloqueado","Bloqueada: "&IF(Y11="","falta motivo",Y11),IF(OR(T11="Aprobado",T11="En Trello"),"Cerrada",IF(T11="En revisión","En revisión: "&IF(Z11="","falta revisor",Z11),IF(T11="Analizado","Lista para revisar: analizó "&IF(S11="","falta responsable",S11),IF(S11="","Falta responsable","Ocupada por "&S11)))))) -> Lista para revisar: analizó Juan Fernando | V11: =IF(AND(Z11<>"",Z11=S11),"El revisor no puede ser el responsable",IF(AND(OR(T11="Analizado",T11="En revisión",T11="Aprobado"),W11=""),"Falta la fuente del análisis",IF(AND(OR(T11="Aprobado",T11="En Trello"),Z11=""),"Aprobado sin revisor",""))) | W11: Prompt con IA | X11: Hoja 14, elemento 9: documento (01 Sí, 02 No; 99, 2 y 2), fecha de suscripción, modificación, sustitución o revocación (AAAA-MM-DD, 10 y 10) y código del prestador donde reposa (999999999999, 12 y 12). Numeral 2.1: estructura separada (CRUD). | AA11: 46315 | AC11: Estructura separada por el 2.1. La revocación es una actualización con su fecha, porque la hoja la pone en el mismo campo que la suscripción: resuelve el pendiente 2 de la tanda 3. El código del prestador depende de D-05. Si es catálogo, por el ajuste 2 lo propondría esta fila, la más baja; se deja en V-18, porque allí el código es el dato de la fila y aquí es un componente de la estructura. Eliminar como inactivación: PENDIENTE D-20. Hoja 14: “01: Si”, sin tilde; la referencia escribe “Sí”.
A12: V-11 | B12: B | C12: 10 | D12: Categoría de discapacidad | E12: 14 y 15 | F12: 01 Discapacidad física · 02 Discapacidad visual · 03 Discapacidad auditiva · 04 Discapacidad intelectual · 05 Discapacidad psicosocial (mental) · 06 Sordoceguera · 07 Discapacidad múltiple · 08 Sin discapacidad | G12: 8 | H12: Alfanumérico | I12: 99 | J12: 2 | K12: 2 | L12: No: hay diferencias | M12: 8 | N12: Entidad por 2.3 | O12: Categorías de discapacidad | P12: 3 | Q12: Ninguna cubre el CRUD. HU-004 a HU-006 usan el dato; los escenarios de varias discapacidades cumplen. | R12: 4 historias; IDs en espera de D-17 | S12: Juan Fernando | T12: Analizado | U12: =IF(OR(T12="",T12="Libre"),"Disponible",IF(T12="Bloqueado","Bloqueada: "&IF(Y12="","falta motivo",Y12),IF(OR(T12="Aprobado",T12="En Trello"),"Cerrada",IF(T12="En revisión","En revisión: "&IF(Z12="","falta revisor",Z12),IF(T12="Analizado","Lista para revisar: analizó "&IF(S12="","falta responsable",S12),IF(S12="","Falta responsable","Ocupada por "&S12)))))) -> Lista para revisar: analizó Juan Fernando | V12: =IF(AND(Z12<>"",Z12=S12),"El revisor no puede ser el responsable",IF(AND(OR(T12="Analizado",T12="En revisión",T12="Aprobado"),W12=""),"Falta la fuente del análisis",IF(AND(OR(T12="Aprobado",T12="En Trello"),Z12=""),"Aprobado sin revisor",""))) | W12: Prompt con IA | X12: Hojas 14 y 15, elemento 10: 8 valores, alfanumérico, formato 99, longitud 2 y 2. Numeral 2.1: más de una discapacidad. Numeral 2.3: más de 5 opciones. | AA12: 46315 | AC12: Hojas 14 y 15, valor 05: “Discapacidad sicosocial (mental)”, con el paréntesis en la hoja 15; la referencia escribe “psicosocial”. Coinciden conteo, tipo, formato y longitudes. Varias discapacidades por paciente (2.1): relación de muchos a muchos. La tanda 4a afirma que ningún campo del 2.1 pasa de 5 opciones: esta lista tiene 8. Cargo: PENDIENTE D-02.
A13: V-12 | B13: B | C13: 11 | D13: Código y nombre del país de residencia habitual | E13: 15 | F13: Código a tres caracteres según estándar ISO 3166-1. Nombre correspondiente al código | G13: El anexo no los enumera | H13: Alfanumérico | I13: 999 / sin formato | J13: 3 / 200 | K13: 3 / 3 | L13: Sí | M13: No los enumera | N13: Reutiliza otra entidad | O13: Países | P13: 4 | Q13: HU-018 a HU-021 (catálogo de países). HU-004 a HU-006 no nombran el país de residencia (Ajustar). | R13: ninguna | S13: Juan Fernando | T13: Analizado | U13: =IF(OR(T13="",T13="Libre"),"Disponible",IF(T13="Bloqueado","Bloqueada: "&IF(Y13="","falta motivo",Y13),IF(OR(T13="Aprobado",T13="En Trello"),"Cerrada",IF(T13="En revisión","En revisión: "&IF(Z13="","falta revisor",Z13),IF(T13="Analizado","Lista para revisar: analizó "&IF(S13="","falta responsable",S13),IF(S13="","Falta responsable","Ocupada por "&S13)))))) -> Lista para revisar: analizó Juan Fernando | V13: =IF(AND(Z13<>"",Z13=S13),"El revisor no puede ser el responsable",IF(AND(OR(T13="Analizado",T13="En revisión",T13="Aprobado"),W13=""),"Falta la fuente del análisis",IF(AND(OR(T13="Aprobado",T13="En Trello"),Z13=""),"Aprobado sin revisor",""))) | W13: Prompt con IA | X13: Hoja 15, elemento 11: código ISO 3166-1 (3 y 3) y nombre (200 y 3). Mismo catálogo que V-01. Ajuste 2 del prompt: la entidad es de la fila más baja. | AA13: 46315 | AC13: Mismo catálogo que V-01 (ISO 3166-1): no propone historias. Ninguna historia del paciente nombra hoy el país de residencia habitual.
A14: V-13 | B14: B | C14: 12 | D14: Código y nombre del municipio de residencia habitual | E14: 15 | F14: Código según DIVIPOLA del DANE: dos dígitos de departamento y tres de municipio. Nombre correspondiente al código | G14: El anexo no los enumera | H14: Alfanumérico | I14: 99999 / sin formato | J14: 5 / 200 | K14: 5 / 3 | L14: No: hay diferencias | M14: No los enumera | N14: Entidad por 2.3 | O14: Municipios | P14: 2 | Q14: HU-026 a HU-029 cubren el CRUD (Ajustar). HU-004 a HU-006 usan el dato; los escenarios de código DANE cumplen. | R14: ninguna | S14: Juan Fernando | T14: Analizado | U14: =IF(OR(T14="",T14="Libre"),"Disponible",IF(T14="Bloqueado","Bloqueada: "&IF(Y14="","falta motivo",Y14),IF(OR(T14="Aprobado",T14="En Trello"),"Cerrada",IF(T14="En revisión","En revisión: "&IF(Z14="","falta revisor",Z14),IF(T14="Analizado","Lista para revisar: analizó "&IF(S14="","falta responsable",S14),IF(S14="","Falta responsable","Ocupada por "&S14)))))) -> Lista para revisar: analizó Juan Fernando | V14: =IF(AND(Z14<>"",Z14=S14),"El revisor no puede ser el responsable",IF(AND(OR(T14="Analizado",T14="En revisión",T14="Aprobado"),W14=""),"Falta la fuente del análisis",IF(AND(OR(T14="Aprobado",T14="En Trello"),Z14=""),"Aprobado sin revisor",""))) | W14: Prompt con IA | X14: Hoja 15, elemento 12: código DIVIPOLA (alfanumérico, 99999, 5 y 5) y nombre (200 y 3). Numeral 2.1: ciudad con código DANE. Numeral 2.3: catálogo externo. | AA14: 46315 | AC14: Código DIVIPOLA de 5 caracteres: 2 del departamento y 3 del municipio (Medellín 05001; como entero pierde el 0). Supuesto: si la residencia habitual está fuera de Colombia, el municipio no aplica. Fuente y versión: PENDIENTE D-21. Carga desde el archivo oficial: funcionalidad de la historia del catálogo (el docente la da por funcional). La referencia parafrasea los valores permitidos; la hoja escribe “Código del municipio según División Política Administrativa”.
A15: V-14 | B15: C | C15: 13 | D15: Etnia | E15: 15 | F15: 01 Indígena · 02 ROM (Gitanos) · 03 Raizal (San Andrés y Providencia) · 04 Palenquero de San Basilio de Palenque · 05 Negro(a) · 06 Afrocolombiano(a) · 99 Ninguna de las anteriores | G15: 7 | H15: Alfanumérico | I15: 99 | J15: 2 | K15: 2 | L15: Sí | M15: 7 | N15: Entidad por 2.3 | O15: Etnias | P15: 3 | Q15: Ninguna cubre el CRUD. HU-004 a HU-006 no nombran el dato (Ajustar). | R15: 4 historias; IDs en espera de D-17 | S15: Juan Fernando | T15: Analizado | U15: =IF(OR(T15="",T15="Libre"),"Disponible",IF(T15="Bloqueado","Bloqueada: "&IF(Y15="","falta motivo",Y15),IF(OR(T15="Aprobado",T15="En Trello"),"Cerrada",IF(T15="En revisión","En revisión: "&IF(Z15="","falta revisor",Z15),IF(T15="Analizado","Lista para revisar: analizó "&IF(S15="","falta responsable",S15),IF(S15="","Falta responsable","Ocupada por "&S15)))))) -> Lista para revisar: analizó Juan Fernando | V15: =IF(AND(Z15<>"",Z15=S15),"El revisor no puede ser el responsable",IF(AND(OR(T15="Analizado",T15="En revisión",T15="Aprobado"),W15=""),"Falta la fuente del análisis",IF(AND(OR(T15="Aprobado",T15="En Trello"),Z15=""),"Aprobado sin revisor",""))) | W15: Prompt con IA | X15: Hoja 15, elemento 13: 7 valores (01 a 06 y 99), alfanumérico, formato 99, longitud 2 y 2. Numeral 2.3: más de 5 opciones. | AA15: 46315 | AC15: Lista de 7 valores. Cargo: PENDIENTE D-02. Representación del código: PENDIENTE D-18. Lectura dudosa: el escaneo de la hoja 15 muestra “Indigena”, posiblemente sin tilde; confirmar en el impreso. Si no la tiene, L pasa a “No: hay diferencias”.
A16: V-15 | B16: C | C16: 13 | D16: Comunidad étnica | E16: 15 | F16: Según catálogo de referencia de comunidades étnicas vigente | G16: El anexo no los enumera | H16: Alfanumérico | I16: 999 | J16: 3 | K16: 3 | L16: No: hay diferencias | M16: No los enumera | N16: Entidad por 2.3 | O16: Comunidades étnicas | P16: 2 | Q16: Ninguna cubre el CRUD. HU-004 a HU-006 no nombran el dato (Ajustar). | R16: 4 historias; IDs en espera de D-17 | S16: Juan Fernando | T16: Analizado | U16: =IF(OR(T16="",T16="Libre"),"Disponible",IF(T16="Bloqueado","Bloqueada: "&IF(Y16="","falta motivo",Y16),IF(OR(T16="Aprobado",T16="En Trello"),"Cerrada",IF(T16="En revisión","En revisión: "&IF(Z16="","falta revisor",Z16),IF(T16="Analizado","Lista para revisar: analizó "&IF(S16="","falta responsable",S16),IF(S16="","Falta responsable","Ocupada por "&S16)))))) -> Lista para revisar: analizó Juan Fernando | V16: =IF(AND(Z16<>"",Z16=S16),"El revisor no puede ser el responsable",IF(AND(OR(T16="Analizado",T16="En revisión",T16="Aprobado"),W16=""),"Falta la fuente del análisis",IF(AND(OR(T16="Aprobado",T16="En Trello"),Z16=""),"Aprobado sin revisor",""))) | W16: Prompt con IA | X16: Hoja 15, elemento 13: “según catálogo de comunidades étnicas vigente”, alfanumérico, 999, 3 y 3. Numeral 2.3: catálogo externo. | AA16: 46315 | AC16: Que cada comunidad pertenezca a una etnia es inferencia del modelo por la definición de la hoja; no se agrega como regla. Fuente y versión del catálogo: PENDIENTE D-21. La hoja escribe “Según catálogo de referencia de comunidades étnicas, según catálogo de comunidades étnicas vigente”; la referencia lo acorta.
A17: V-16 | B17: C | C17: 14 | D17: Zona territorial de residencia | E17: 15 | F17: 01 Urbana · 02 Rural | G17: 2 | H17: Alfanumérico | I17: 99 | J17: 2 | K17: 2 | L17: Sí | M17: 2 | N17: Campo del paciente | O17: Paciente | P17: 5 | Q17: HU-004, HU-005, HU-006 no nombran el dato (Ajustar). | R17: ninguna | S17: Juan Fernando | T17: Analizado | U17: =IF(OR(T17="",T17="Libre"),"Disponible",IF(T17="Bloqueado","Bloqueada: "&IF(Y17="","falta motivo",Y17),IF(OR(T17="Aprobado",T17="En Trello"),"Cerrada",IF(T17="En revisión","En revisión: "&IF(Z17="","falta revisor",Z17),IF(T17="Analizado","Lista para revisar: analizó "&IF(S17="","falta responsable",S17),IF(S17="","Falta responsable","Ocupada por "&S17)))))) -> Lista para revisar: analizó Juan Fernando | V17: =IF(AND(Z17<>"",Z17=S17),"El revisor no puede ser el responsable",IF(AND(OR(T17="Analizado",T17="En revisión",T17="Aprobado"),W17=""),"Falta la fuente del análisis",IF(AND(OR(T17="Aprobado",T17="En Trello"),Z17=""),"Aprobado sin revisor",""))) | W17: Prompt con IA | X17: Hoja 15, elemento 14: 2 valores, alfanumérico, formato 99, longitud 2 y 2. Numeral 2.3: no llega a más de 5 opciones. | AA17: 46315 | AC17: Lista de 2 valores. Campo del paciente.
A18: V-17 | B18: C | C18: 15 | D18: Código y nombre de la entidad que responde por el plan de beneficios | E18: 15 y 16 | F18: EPS, entidades adaptadas, regímenes especial y de excepción, fondo de población privada de la libertad, secretarías e institutos de salud, aseguradoras SOAT, planes voluntarios y ARL, según catálogo del Ministerio de Salud. Si la atención es particular, la secretaría de salud del lugar | G18: El anexo no los enumera | H18: Alfanumérico | I18: 999999 / sin formato | J18: 6 / 200 | K18: 6 / 3 | L18: No: hay diferencias | M18: No los enumera | N18: Entidad por 2.3 | O18: Entidades administradoras de planes de beneficios | P18: 2 | Q18: Ninguna cubre el CRUD. HU-004 a HU-006 no nombran el dato (Ajustar). | R18: 4 historias; IDs en espera de D-17 | S18: Juan Fernando | T18: Analizado | U18: =IF(OR(T18="",T18="Libre"),"Disponible",IF(T18="Bloqueado","Bloqueada: "&IF(Y18="","falta motivo",Y18),IF(OR(T18="Aprobado",T18="En Trello"),"Cerrada",IF(T18="En revisión","En revisión: "&IF(Z18="","falta revisor",Z18),IF(T18="Analizado","Lista para revisar: analizó "&IF(S18="","falta responsable",S18),IF(S18="","Falta responsable","Ocupada por "&S18)))))) -> Lista para revisar: analizó Juan Fernando | V18: =IF(AND(Z18<>"",Z18=S18),"El revisor no puede ser el responsable",IF(AND(OR(T18="Analizado",T18="En revisión",T18="Aprobado"),W18=""),"Falta la fuente del análisis",IF(AND(OR(T18="Aprobado",T18="En Trello"),Z18=""),"Aprobado sin revisor",""))) | W18: Prompt con IA | X18: Hojas 15 y 16, elemento 15: código (alfanumérico, 999999, 6 y 6) y nombre (200 y 3), “según catálogo que establezca el Ministerio de Salud y Protección Social”. Numeral 2.3: catálogo externo. | AA18: 46315 | AC18: La referencia resume el texto de los valores permitidos; coinciden código y nombre. Fuente y versión del catálogo: PENDIENTE D-21. Si la atención es particular, el código es el de la secretaría de salud del lugar donde se prestó (hoja 16).
A19: V-18 | B19: C | C19: 16 | D19: Código del prestador de servicios de salud que realiza la atención | E19: 16 | F19: Código asignado en el SGSSS a los prestadores inscritos en el REPS, o asignado por el Ministerio en casos de excepción, publicados en SISPRO | G19: El anexo no los enumera | H19: Alfanumérico | I19: 999999999999 | J19: 12 | K19: 12 | L19: No: hay diferencias | M19: No los enumera | N19: Pendiente de decisión | O19: Prestadores si D-05 lo hace catálogo; si no, Atención | Q19: HU-007, HU-008, HU-009 usan el código (Ajustar). | R19: 4 historias si D-05 lo hace catálogo; IDs en espera de D-17 | S19: Juan Fernando | T19: Bloqueado | U19: =IF(OR(T19="",T19="Libre"),"Disponible",IF(T19="Bloqueado","Bloqueada: "&IF(Y19="","falta motivo",Y19),IF(OR(T19="Aprobado",T19="En Trello"),"Cerrada",IF(T19="En revisión","En revisión: "&IF(Z19="","falta revisor",Z19),IF(T19="Analizado","Lista para revisar: analizó "&IF(S19="","falta responsable",S19),IF(S19="","Falta responsable","Ocupada por "&S19)))))) -> Bloqueada: D-05 | V19: =IF(AND(Z19<>"",Z19=S19),"El revisor no puede ser el responsable",IF(AND(OR(T19="Analizado",T19="En revisión",T19="Aprobado"),W19=""),"Falta la fuente del análisis",IF(AND(OR(T19="Aprobado",T19="En Trello"),Z19=""),"Aprobado sin revisor",""))) | W19: Prompt con IA | X19: Hoja 16, elemento 16: código del REPS publicado en SISPRO, alfanumérico, 999999999999, 12 y 12. D-05. | Y19: D-05 | AA19: 46315 | AC19: Si es catálogo propio depende de D-05. Para una sola IPS, el prestador que realiza la atención puede ser fijo (sus sedes); el del elemento 9 puede ser cualquier prestador del país. Fila bloqueada hasta D-05. La referencia parafrasea el texto de los valores permitidos de la hoja 16.
A20: V-19 | B20: C | C20: 17 | D20: Fecha y hora de inicio de la atención | E20: 16 | F20: Sin lista | G20: No aplica: dato abierto | H20: Fecha | I20: AAAA-MM-DD HH:MM | J20: 16 | K20: 16 | L20: No: hay diferencias | M20: No aplica | N20: Campo de la atención | O20: Atención | P20: 5 | Q20: HU-007, HU-008, HU-009 (Ajustar). | R20: ninguna | S20: Juan Fernando | T20: Analizado | U20: =IF(OR(T20="",T20="Libre"),"Disponible",IF(T20="Bloqueado","Bloqueada: "&IF(Y20="","falta motivo",Y20),IF(OR(T20="Aprobado",T20="En Trello"),"Cerrada",IF(T20="En revisión","En revisión: "&IF(Z20="","falta revisor",Z20),IF(T20="Analizado","Lista para revisar: analizó "&IF(S20="","falta responsable",S20),IF(S20="","Falta responsable","Ocupada por "&S20)))))) -> Lista para revisar: analizó Juan Fernando | V20: =IF(AND(Z20<>"",Z20=S20),"El revisor no puede ser el responsable",IF(AND(OR(T20="Analizado",T20="En revisión",T20="Aprobado"),W20=""),"Falta la fuente del análisis",IF(AND(OR(T20="Aprobado",T20="En Trello"),Z20=""),"Aprobado sin revisor",""))) | W20: Prompt con IA | X20: Hoja 16, elemento 17: Fecha, longitud 16 y 16. Retroalimentación HU-007 ampliada: concretar fecha/hora. | AA20: 46315 | AC20: La hoja 16 imprime el formato “AAAA-MM-DD HH MM”, sin dos puntos; los elementos 4 y 22 traen “HH:MM” y la longitud es 16 en los dos casos. Se asume “HH:MM”: supuesto a confirmar. La hora es obligatoria (mínima 16).
A21: V-20 | B21: C | C21: 18 | D21: Modalidad de realización | E21: 16 | F21: 01 Intramural · 02 Extramural unidad móvil · 03 Extramural domiciliaria · 04 Extramural jornada de salud · 05 Extramural (atención prehospitalaria o transporte asistencial) · 06 Telemedicina interactiva · 07 Telemedicina no interactiva · 08 Telemedicina, telexperticia · 09 Telemedicina, telemonitoreo | G21: 9 | H21: Alfanumérico | I21: 99 | J21: 2 | K21: 2 | L21: No: hay diferencias | M21: 9 | N21: Entidad por 2.3 | O21: Modalidades de realización | P21: 3 | Q21: Ninguna cubre el CRUD. HU-007, HU-008 y HU-009 usan el dato (Ajustar). | R21: 4 historias; IDs en espera de D-17 | S21: Juan Fernando | T21: Analizado | U21: =IF(OR(T21="",T21="Libre"),"Disponible",IF(T21="Bloqueado","Bloqueada: "&IF(Y21="","falta motivo",Y21),IF(OR(T21="Aprobado",T21="En Trello"),"Cerrada",IF(T21="En revisión","En revisión: "&IF(Z21="","falta revisor",Z21),IF(T21="Analizado","Lista para revisar: analizó "&IF(S21="","falta responsable",S21),IF(S21="","Falta responsable","Ocupada por "&S21)))))) -> Lista para revisar: analizó Juan Fernando | V21: =IF(AND(Z21<>"",Z21=S21),"El revisor no puede ser el responsable",IF(AND(OR(T21="Analizado",T21="En revisión",T21="Aprobado"),W21=""),"Falta la fuente del análisis",IF(AND(OR(T21="Aprobado",T21="En Trello"),Z21=""),"Aprobado sin revisor",""))) | W21: Prompt con IA | X21: Hoja 16, elemento 18: 9 valores, alfanumérico, formato 99, longitud 2 y 2. Numeral 2.3: más de 5 opciones. Retroalimentación HU-007 ampliada: concretar modalidad/grupo. | AA21: 46315 | AC21: Hoja 16: valor 05 “Extramural (atención pre hospitalaria o transporte asistencial)”; 08 “Telemedicina – Telexperticia”; 09 “Telemedicina – Telemonitoreo”. La referencia escribe “prehospitalaria” y separa con coma. Coinciden conteo, tipo, formato y longitudes. Cargo: PENDIENTE D-02. La referencia además escribe “telexperticia” y “telemonitoreo” en minúscula.
A22: V-21 | B22: C | C22: 18 | D22: Grupo de servicios | E22: 16 | F22: 01 Consulta externa · 02 Apoyo diagnóstico y complementación terapéutica · 03 Internación · 04 Quirúrgico · 05 Atención inmediata | G22: 5 | H22: Alfanumérico | I22: 99 | J22: 2 | K22: 2 | L22: No: hay diferencias | M22: 5 | N22: Campo de la atención | O22: Atención | P22: 5 | Q22: HU-007, HU-008, HU-009 (Ajustar). | R22: ninguna | S22: Juan Fernando | T22: Analizado | U22: =IF(OR(T22="",T22="Libre"),"Disponible",IF(T22="Bloqueado","Bloqueada: "&IF(Y22="","falta motivo",Y22),IF(OR(T22="Aprobado",T22="En Trello"),"Cerrada",IF(T22="En revisión","En revisión: "&IF(Z22="","falta revisor",Z22),IF(T22="Analizado","Lista para revisar: analizó "&IF(S22="","falta responsable",S22),IF(S22="","Falta responsable","Ocupada por "&S22)))))) -> Lista para revisar: analizó Juan Fernando | V22: =IF(AND(Z22<>"",Z22=S22),"El revisor no puede ser el responsable",IF(AND(OR(T22="Analizado",T22="En revisión",T22="Aprobado"),W22=""),"Falta la fuente del análisis",IF(AND(OR(T22="Aprobado",T22="En Trello"),Z22=""),"Aprobado sin revisor",""))) | W22: Prompt con IA | X22: Hoja 16, elemento 18: 5 valores, alfanumérico, formato 99, longitud 2 y 2. Numeral 2.3: no llega a más de 5 opciones. D-01. | AA22: 46315 | AC22: Lista de exactamente 5 valores. Depende de D-01: si el umbral pasa a 5 o más, cambia a Entidad por 2.3 con 4 historias nuevas. La hoja escribe el valor 05 con mayúscula: “Atención Inmediata”.
A23: V-22 | B23: D | C23: 19 | D23: Entorno donde se realiza la atención | E23: 16 | F23: 01 Hogar · 02 Comunitario · 03 Escolar · 04 Laboral · 05 Institucional | G23: 5 | H23: Alfanumérico | I23: 99 | J23: 2 | K23: 2 | L23: Sí | M23: 5 | N23: Campo de la atención | O23: Atención | P23: 5 | Q23: HU-007, HU-008, HU-009 | R23: ninguna | S23: Juan Fernando | T23: Analizado | U23: =IF(OR(T23="",T23="Libre"),"Disponible",IF(T23="Bloqueado","Bloqueada: "&IF(Y23="","falta motivo",Y23),IF(OR(T23="Aprobado",T23="En Trello"),"Cerrada",IF(T23="En revisión","En revisión: "&IF(Z23="","falta revisor",Z23),IF(T23="Analizado","Lista para revisar: analizó "&IF(S23="","falta responsable",S23),IF(S23="","Falta responsable","Ocupada por "&S23)))))) -> Lista para revisar: analizó Juan Fernando | V23: =IF(AND(Z23<>"",Z23=S23),"El revisor no puede ser el responsable",IF(AND(OR(T23="Analizado",T23="En revisión",T23="Aprobado"),W23=""),"Falta la fuente del análisis",IF(AND(OR(T23="Aprobado",T23="En Trello"),Z23=""),"Aprobado sin revisor",""))) | W23: Prompt con IA | X23: Hoja 16, elemento 19: 5 valores, alfanumérico, formato 99, longitud 2 y 2. Numeral 2.3: no llega a más de 5 opciones. D-01. Retroalimentación HU-007, revisión ampliada: concretar entorno. | AA23: 46313 | AC23: Lista de exactamente 5 valores. Depende de D-01: si el umbral pasa a 5 o más, cambia a Entidad por 2.3 con 4 historias nuevas. Obligatoriedad del dato: PENDIENTE D-15. Se guarda como texto de 2 caracteres: PENDIENTE D-18.
A24: V-23 | B24: D | C24: 20 | D24: Vía de ingreso del usuario al servicio de salud | E24: 16 y 17 | F24: 01 Demanda espontánea · 02 Derivado de consulta externa · 03 Derivado de urgencias · 04 Derivado de hospitalización · 05 Derivado de sala de cirugía · 06 Derivado de sala de partos · 07 Recién nacido en la institución · 08 Recién nacido en otra institución · 09 Derivado o referido de hospitalización domiciliaria · 10 Derivado de atención domiciliaria · 11 Derivado de telemedicina · 12 Derivado de jornada de salud · 13 Referido de otra institución · 14 Contrarreferido de otra institución | G24: 14 | H24: Alfanumérico | I24: 99 | J24: 2 | K24: 2 | L24: No: hay diferencias | M24: 14 | N24: Entidad por 2.3 | O24: Vía de ingreso | P24: 3 | Q24: Ninguna cubre el CRUD. HU-007, HU-008 y HU-009 usan el dato (Ajustar). | R24: 4 historias; IDs en espera de D-17 | S24: Juan Fernando | T24: Analizado | U24: =IF(OR(T24="",T24="Libre"),"Disponible",IF(T24="Bloqueado","Bloqueada: "&IF(Y24="","falta motivo",Y24),IF(OR(T24="Aprobado",T24="En Trello"),"Cerrada",IF(T24="En revisión","En revisión: "&IF(Z24="","falta revisor",Z24),IF(T24="Analizado","Lista para revisar: analizó "&IF(S24="","falta responsable",S24),IF(S24="","Falta responsable","Ocupada por "&S24)))))) -> Lista para revisar: analizó Juan Fernando | V24: =IF(AND(Z24<>"",Z24=S24),"El revisor no puede ser el responsable",IF(AND(OR(T24="Analizado",T24="En revisión",T24="Aprobado"),W24=""),"Falta la fuente del análisis",IF(AND(OR(T24="Aprobado",T24="En Trello"),Z24=""),"Aprobado sin revisor",""))) | W24: Prompt con IA | X24: Hojas 16 y 17, elemento 20: 14 valores, alfanumérico, formato 99, longitud 2 y 2. Numeral 2.3: más de 5 opciones. Retroalimentación General ampliada: cobertura de todos los catálogos con más de cinco opciones. HU-007 ampliada: concretar vía. | AA24: 46313 | AC24: Hoja 17, valor 14: “Contra referido de otra institución”; la referencia escribe “Contrarreferido”. Coinciden conteo, tipo, formato y longitudes. Entidad con código de 2 caracteres, guardado como texto para conservar el cero inicial, y nombre. La atención guarda el código de la vía. Por el artículo 7 de la Resolución 866, el catálogo solo refleja los valores de la hoja. Cargo que mantiene el catálogo: PENDIENTE D-02. Obligatoriedad en la atención: PENDIENTE D-15. Representación del código: PENDIENTE D-18.
A25: V-24 | B25: D | C25: 21 | D25: Causa que motiva la atención | E25: 17 | F25: 21 Accidente de trabajo · 22 Accidente en el hogar · 23 Accidente de tránsito de origen común · 24 Accidente de tránsito de origen laboral · 25 Accidente en el entorno educativo · 26 Otro tipo de accidente · 27 Evento catastrófico de origen natural · 28 Lesión por agresión · 29 Lesión autoinfligida · 30 Sospecha de violencia física · 31 Sospecha de violencia psicológica · 32 Sospecha de violencia sexual · 33 Sospecha de negligencia y abandono · 34 IVE relacionado con peligro a la salud o vida de la mujer · 35 IVE por malformación congénita incompatible con la vida · 36 IVE por violencia sexual, incesto o por inseminación artificial o transferencia de óvulo fecundado no consentida · 37 Evento adverso en salud · 38 Enfermedad general · 39 Enfermedad laboral · 40 Promoción y mantenimiento de la salud, intervenciones individuales · 41 Intervención colectiva · 42 Atención de población materno perinatal · 43 Seguridad y salud en el trabajo · 44 Otros eventos catastróficos · 45 Accidente de mina antipersonal (MAP) · 46 Accidente de artefacto explosivo improvisado (AEI) · 47 Accidente de munición sin explotar (MUSE) · 48 Otra víctima de conflicto armado colombiano · 49 Riesgo ambiental | G25: 29 | H25: Alfanumérico | I25: 99 | J25: 2 | K25: 2 | L25: No: hay diferencias | M25: 29 | N25: Entidad por 2.3 | O25: Causa que motiva la atención | P25: 3 | Q25: Ninguna cubre el CRUD. HU-007, HU-008 y HU-009 usan el dato (Ajustar). | R25: 4 historias; IDs en espera de D-17 | S25: Juan Fernando | T25: Analizado | U25: =IF(OR(T25="",T25="Libre"),"Disponible",IF(T25="Bloqueado","Bloqueada: "&IF(Y25="","falta motivo",Y25),IF(OR(T25="Aprobado",T25="En Trello"),"Cerrada",IF(T25="En revisión","En revisión: "&IF(Z25="","falta revisor",Z25),IF(T25="Analizado","Lista para revisar: analizó "&IF(S25="","falta responsable",S25),IF(S25="","Falta responsable","Ocupada por "&S25)))))) -> Lista para revisar: analizó Juan Fernando | V25: =IF(AND(Z25<>"",Z25=S25),"El revisor no puede ser el responsable",IF(AND(OR(T25="Analizado",T25="En revisión",T25="Aprobado"),W25=""),"Falta la fuente del análisis",IF(AND(OR(T25="Aprobado",T25="En Trello"),Z25=""),"Aprobado sin revisor",""))) | W25: Prompt con IA | X25: Hoja 17, elemento 21: 29 valores (códigos 21 a 49), alfanumérico, formato 99, longitud 2 y 2. Numeral 2.3: más de 5 opciones. Retroalimentación General ampliada: cobertura de catálogos con más de cinco opciones. HU-007 ampliada: concretar causa. | AA25: 46313 | AC25: Hoja 17: el valor 29 dice “Lesión auto infligida”; el 40, “Promoción y mantenimiento de la salud-Intervenciones individuales.”; del 45 al 47 la sigla va después de un guion y no entre paréntesis; en el 43, 44, 46 y 47 la referencia quitó mayúsculas. Coinciden conteo, tipo, formato y longitudes. Los nombres del catálogo se toman de la hoja. El 36 dice “ovulo”, sin tilde. Entidad con código de 2 caracteres y nombre. La hoja no cita catálogo externo: sus 29 valores son la fuente oficial y, por el artículo 7 de la Resolución 866, la IPS no agrega otros. Cargo: PENDIENTE D-02. Obligatoriedad en la atención: PENDIENTE D-15. Representación del código: PENDIENTE D-18. Valor 27: la hoja escribe “orígen natural”, con tilde; la referencia, “origen”.
A26: V-25 | B26: D | C26: 22 | D26: Fecha, hora y clasificación del triage | E26: 17 y 18 | F26: Fecha y hora del triage. Clasificación: 01 Triage I · 02 Triage II · 03 Triage III · 04 Triage IV · 05 Triage V | G26: 5 | H26: Fecha / Alfanumérico | I26: AAAA-MM-DD HH:MM / 99 | J26: 16 / 2 | K26: 16 / 2 | L26: Sí | M26: 5 | N26: Campo de la atención | O26: Atención | P26: 5 | Q26: HU-007, HU-008, HU-009 | R26: ninguna | S26: Juan Fernando | T26: Analizado | U26: =IF(OR(T26="",T26="Libre"),"Disponible",IF(T26="Bloqueado","Bloqueada: "&IF(Y26="","falta motivo",Y26),IF(OR(T26="Aprobado",T26="En Trello"),"Cerrada",IF(T26="En revisión","En revisión: "&IF(Z26="","falta revisor",Z26),IF(T26="Analizado","Lista para revisar: analizó "&IF(S26="","falta responsable",S26),IF(S26="","Falta responsable","Ocupada por "&S26)))))) -> Lista para revisar: analizó Juan Fernando | V26: =IF(AND(Z26<>"",Z26=S26),"El revisor no puede ser el responsable",IF(AND(OR(T26="Analizado",T26="En revisión",T26="Aprobado"),W26=""),"Falta la fuente del análisis",IF(AND(OR(T26="Aprobado",T26="En Trello"),Z26=""),"Aprobado sin revisor",""))) | W26: Prompt con IA | X26: Hojas 17 y 18, elemento 22: fecha y hora (Fecha, AAAA-MM-DD HH:MM, 16 y 16) y clasificación (5 valores, alfanumérico, 99, 2 y 2). Numeral 2.3: no llega a más de 5 opciones. D-01, D-13. Retroalimentación HU-007, revisión ampliada: “triage cuando corresponda”. | AA26: 46313 | AC26: Dos componentes. Fecha y hora del triage: Fecha, AAAA-MM-DD HH:MM, 16 y 16. Clasificación: 5 valores, formato 99, 2 y 2; depende de D-01. La hoja 18 completa la definición: prioridad de la atención en un servicio de urgencias. Los dos componentes son campos de la atención. Si el umbral pasa a 5 o más, la clasificación cambia a Entidad por 2.3 con 4 historias nuevas. La fecha exige hora (mínima 16), a diferencia de la fecha de nacimiento (mínima 10). Cuándo se exige: PENDIENTE D-13. La fecha se guarda como fecha y hora; la clasificación como texto de 2: PENDIENTE D-18.
A27: V-26 | B27: D | C27: 23 | D27: Código y nombre del diagnóstico principal de ingreso | E27: 18 | F27: Código del diagnóstico confirmado o presuntivo según catálogo CIE-10 vigente. Nombre correspondiente al código | G27: El anexo no los enumera | H27: Alfanumérico | I27: 9999 / sin formato | J27: 4 / 200 | K27: 4 / 3 | L27: No: hay diferencias | M27: No los enumera | N27: Entidad por 2.3 | O27: Diagnósticos CIE-10 | P27: 2 | Q27: HU-030, HU-031, HU-032, HU-033 cubren el CRUD (Ajustar). HU-007, HU-008 y HU-009 usan el código (Ajustar). | R27: ninguna | S27: Juan Fernando | T27: Analizado | U27: =IF(OR(T27="",T27="Libre"),"Disponible",IF(T27="Bloqueado","Bloqueada: "&IF(Y27="","falta motivo",Y27),IF(OR(T27="Aprobado",T27="En Trello"),"Cerrada",IF(T27="En revisión","En revisión: "&IF(Z27="","falta revisor",Z27),IF(T27="Analizado","Lista para revisar: analizó "&IF(S27="","falta responsable",S27),IF(S27="","Falta responsable","Ocupada por "&S27)))))) -> Lista para revisar: analizó Juan Fernando | V27: =IF(AND(Z27<>"",Z27=S27),"El revisor no puede ser el responsable",IF(AND(OR(T27="Analizado",T27="En revisión",T27="Aprobado"),W27=""),"Falta la fuente del análisis",IF(AND(OR(T27="Aprobado",T27="En Trello"),Z27=""),"Aprobado sin revisor",""))) | W27: Prompt con IA | X27: Hoja 18, elemento 23: código CIE-10 (alfanumérico, formato 9999, longitud 4 y 4) y nombre correspondiente al código (alfanumérico, 200 y 3). Numeral 2.2: última versión del CIE-10 y jerarquía padre-hijo. Numeral 2.3. HU-007 ampliada: diagnóstico principal/tipo. | AA27: 46313 | AC27: Hoja 18: “catálogo de CIE10 vigente”. Versión: PENDIENTE D-09. Código y nombre en la misma entidad: el nombre es el que corresponde al código, no texto libre. Si un código padre se puede asociar a una atención: D-22 (propuesta: no, por la longitud 4 y 4). Carga desde el archivo oficial: funcionalidad de la historia del catálogo (el docente la da por funcional). La referencia parafrasea los valores permitidos; la hoja escribe “de acuerdo catálogo CIE10 y las normas que la modifiquen”.
A28: V-27 | B28: D | C28: 23 | D28: Código de enfermedad huérfana | E28: 18 | F28: En caso de presentar una enfermedad huérfana, código del catálogo de enfermedades huérfanas vigente | G28: El anexo no los enumera | H28: Alfanumérico | I28: 9999 | J28: 4 | K28: 1 | L28: No: hay diferencias | M28: No los enumera | N28: Entidad por 2.3 | O28: Enfermedades huérfanas | P28: 2 | Q28: Ninguna cubre el CRUD. HU-007, HU-008 y HU-009 usan el dato (Ajustar). | R28: 4 historias; IDs en espera de D-17 | S28: Juan Fernando | T28: Analizado | U28: =IF(OR(T28="",T28="Libre"),"Disponible",IF(T28="Bloqueado","Bloqueada: "&IF(Y28="","falta motivo",Y28),IF(OR(T28="Aprobado",T28="En Trello"),"Cerrada",IF(T28="En revisión","En revisión: "&IF(Z28="","falta revisor",Z28),IF(T28="Analizado","Lista para revisar: analizó "&IF(S28="","falta responsable",S28),IF(S28="","Falta responsable","Ocupada por "&S28)))))) -> Lista para revisar: analizó Juan Fernando | V28: =IF(AND(Z28<>"",Z28=S28),"El revisor no puede ser el responsable",IF(AND(OR(T28="Analizado",T28="En revisión",T28="Aprobado"),W28=""),"Falta la fuente del análisis",IF(AND(OR(T28="Aprobado",T28="En Trello"),Z28=""),"Aprobado sin revisor",""))) | W28: Prompt con IA | X28: Hoja 18, elemento 23: código de enfermedad huérfana, alfanumérico, 9999, longitud 4 y 1, “según catálogo de enfermedades huérfanas vigente”. Numeral 2.3: catálogo externo. D-14. | AA28: 46313 | AC28: En la hoja este componente no tiene nombre propio: es la segunda línea de “Código del diagnóstico principal”, y aplica solo “en caso de presentar” una enfermedad huérfana. Longitud mínima 1, máxima 4. Catálogo distinto del CIE-10: la hoja lo nombra aparte y sus longitudes (1 a 4) no son las del CIE-10 (4 y 4). Fuente y versión: PENDIENTE D-14. Dato opcional de la atención: solo si el paciente la presenta. La referencia parafrasea el texto de la hoja sobre enfermedades huérfanas.
A29: V-28 | B29: D | C29: 23 | D29: Tipo de diagnóstico principal de ingreso | E29: 18 | F29: 01 Impresión diagnóstica · 02 Confirmado nuevo · 03 Confirmado repetido | G29: 3 | H29: Alfanumérico | I29: 99 | J29: 2 | K29: 2 | L29: Sí | M29: 3 | N29: Campo de la atención | O29: Atención | P29: 5 | Q29: HU-007, HU-008, HU-009 (Ajustar). | R29: ninguna | S29: Juan Fernando | T29: Analizado | U29: =IF(OR(T29="",T29="Libre"),"Disponible",IF(T29="Bloqueado","Bloqueada: "&IF(Y29="","falta motivo",Y29),IF(OR(T29="Aprobado",T29="En Trello"),"Cerrada",IF(T29="En revisión","En revisión: "&IF(Z29="","falta revisor",Z29),IF(T29="Analizado","Lista para revisar: analizó "&IF(S29="","falta responsable",S29),IF(S29="","Falta responsable","Ocupada por "&S29)))))) -> Lista para revisar: analizó Juan Fernando | V29: =IF(AND(Z29<>"",Z29=S29),"El revisor no puede ser el responsable",IF(AND(OR(T29="Analizado",T29="En revisión",T29="Aprobado"),W29=""),"Falta la fuente del análisis",IF(AND(OR(T29="Aprobado",T29="En Trello"),Z29=""),"Aprobado sin revisor",""))) | W29: Prompt con IA | X29: Hoja 18, elemento 23: tipo de diagnóstico, 3 valores, alfanumérico, formato 99, longitud 2 y 2. Numeral 2.3: no llega a más de 5 opciones. | AA29: 46313 | AC29: Lista de 3 valores. Campo de la atención.

Sheet Entidades
